2023-03-02 09:10:15.987|ERROR|6986:123145416929280|users.py:20|users.test|This is log error
2023-03-02 09:10:15.990|ERROR|6986:123145416929280|logger.py:75|logger._append_exc|this is log exception
Traceback (most recent call last):
  File "/usr/local/Cellar/python/3.7.2_2/Frameworks/Python.framework/Versions/3.7/lib/python3.7/threading.py", line 885, in _bootstrap
    self._bootstrap_inner()
  File "/usr/local/Cellar/python/3.7.2_2/Frameworks/Python.framework/Versions/3.7/lib/python3.7/threading.py", line 917, in _bootstrap_inner
    self.run()
  File "/usr/local/Cellar/python/3.7.2_2/Frameworks/Python.framework/Versions/3.7/lib/python3.7/threading.py", line 865, in run
    self._target(*self._args, **self._kwargs)
  File "/usr/local/Cellar/python/3.7.2_2/Frameworks/Python.framework/Versions/3.7/lib/python3.7/socketserver.py", line 650, in process_request_thread
    self.finish_request(request, client_address)
  File "/usr/local/Cellar/python/3.7.2_2/Frameworks/Python.framework/Versions/3.7/lib/python3.7/socketserver.py", line 360, in finish_request
    self.RequestHandlerClass(request, client_address, self)
  File "/usr/local/Cellar/python/3.7.2_2/Frameworks/Python.framework/Versions/3.7/lib/python3.7/socketserver.py", line 720, in __init__
    self.handle()
  File "/Users/phucluu/Documents/GitHub/django-core-api/polls/start/venv/lib/python3.7/site-packages/django/core/servers/basehttp.py", line 176, in handle
    self.handle_one_request()
  File "/Users/phucluu/Documents/GitHub/django-core-api/polls/start/venv/lib/python3.7/site-packages/django/core/servers/basehttp.py", line 201, in handle_one_request
    handler.run(self.server.get_app())
  File "/usr/local/Cellar/python/3.7.2_2/Frameworks/Python.framework/Versions/3.7/lib/python3.7/wsgiref/handlers.py", line 137, in run
    self.result = application(self.environ, self.start_response)
  File "/Users/phucluu/Documents/GitHub/django-core-api/polls/start/venv/lib/python3.7/site-packages/django/contrib/staticfiles/handlers.py", line 76, in __call__
    return self.application(environ, start_response)
  File "/Users/phucluu/Documents/GitHub/django-core-api/polls/start/venv/lib/python3.7/site-packages/django/core/handlers/wsgi.py", line 133, in __call__
    response = self.get_response(request)
  File "/Users/phucluu/Documents/GitHub/django-core-api/polls/start/venv/lib/python3.7/site-packages/django/core/handlers/base.py", line 130, in get_response
    response = self._middleware_chain(request)
  File "/Users/phucluu/Documents/GitHub/django-core-api/polls/start/venv/lib/python3.7/site-packages/django/core/handlers/exception.py", line 47, in inner
    response = get_response(request)
  File "/Users/phucluu/Documents/GitHub/django-core-api/polls/start/venv/lib/python3.7/site-packages/django/utils/deprecation.py", line 117, in __call__
    response = response or self.get_response(request)
  File "/Users/phucluu/Documents/GitHub/django-core-api/polls/start/venv/lib/python3.7/site-packages/django/core/handlers/exception.py", line 47, in inner
    response = get_response(request)
  File "/Users/phucluu/Documents/GitHub/django-core-api/polls/start/venv/lib/python3.7/site-packages/django/utils/deprecation.py", line 117, in __call__
    response = response or self.get_response(request)
  File "/Users/phucluu/Documents/GitHub/django-core-api/polls/start/venv/lib/python3.7/site-packages/django/core/handlers/exception.py", line 47, in inner
    response = get_response(request)
  File "/Users/phucluu/Documents/GitHub/django-core-api/polls/start/venv/lib/python3.7/site-packages/django/utils/deprecation.py", line 117, in __call__
    response = response or self.get_response(request)
  File "/Users/phucluu/Documents/GitHub/django-core-api/polls/start/venv/lib/python3.7/site-packages/django/core/handlers/exception.py", line 47, in inner
    response = get_response(request)
  File "/Users/phucluu/Documents/GitHub/django-core-api/polls/start/venv/lib/python3.7/site-packages/django/utils/deprecation.py", line 117, in __call__
    response = response or self.get_response(request)
  File "/Users/phucluu/Documents/GitHub/django-core-api/polls/start/venv/lib/python3.7/site-packages/django/core/handlers/exception.py", line 47, in inner
    response = get_response(request)
  File "/Users/phucluu/Documents/GitHub/django-core-api/polls/start/venv/lib/python3.7/site-packages/django/utils/deprecation.py", line 117, in __call__
    response = response or self.get_response(request)
  File "/Users/phucluu/Documents/GitHub/django-core-api/polls/start/venv/lib/python3.7/site-packages/django/core/handlers/exception.py", line 47, in inner
    response = get_response(request)
  File "/Users/phucluu/Documents/GitHub/django-core-api/polls/start/venv/lib/python3.7/site-packages/django/utils/deprecation.py", line 117, in __call__
    response = response or self.get_response(request)
  File "/Users/phucluu/Documents/GitHub/django-core-api/polls/start/venv/lib/python3.7/site-packages/django/core/handlers/exception.py", line 47, in inner
    response = get_response(request)
  File "/Users/phucluu/Documents/GitHub/django-core-api/polls/start/venv/lib/python3.7/site-packages/django/utils/deprecation.py", line 117, in __call__
    response = response or self.get_response(request)
  File "/Users/phucluu/Documents/GitHub/django-core-api/polls/start/venv/lib/python3.7/site-packages/django/core/handlers/exception.py", line 47, in inner
    response = get_response(request)
  File "/Users/phucluu/Documents/GitHub/django-core-api/polls/start/venv/lib/python3.7/site-packages/django/utils/deprecation.py", line 117, in __call__
    response = response or self.get_response(request)
  File "/Users/phucluu/Documents/GitHub/django-core-api/polls/start/venv/lib/python3.7/site-packages/django/core/handlers/exception.py", line 47, in inner
    response = get_response(request)
  File "/Users/phucluu/Documents/GitHub/django-core-api/polls/start/venv/lib/python3.7/site-packages/django/core/handlers/base.py", line 181, in _get_response
    response = wrapped_callback(request, *callback_args, **callback_kwargs)
  File "/Users/phucluu/Documents/GitHub/django-core-api/polls/start/venv/lib/python3.7/site-packages/django/views/decorators/http.py", line 40, in inner
    return func(request, *args, **kwargs)
  File "/Users/phucluu/Documents/GitHub/django-core-api/polls/start/api/users.py", line 22, in test
    log.exception('this is log exception')
None: None

2023-03-02 09:10:16.001|WARNING|6986:123145416929280|users.py:23|users.test|This is log warning
2023-03-02 09:10:16.002|CRITICAL|6986:123145416929280|users.py:25|users.test|This is log fatal
2023-03-02 09:32:16.048|ERROR|7270:123145492033536|logger.py:75|logger._append_exc|test_exception
Traceback (most recent call last):
  File "/usr/local/Cellar/python/3.7.2_2/Frameworks/Python.framework/Versions/3.7/lib/python3.7/threading.py", line 885, in _bootstrap
    self._bootstrap_inner()
  File "/usr/local/Cellar/python/3.7.2_2/Frameworks/Python.framework/Versions/3.7/lib/python3.7/threading.py", line 917, in _bootstrap_inner
    self.run()
  File "/usr/local/Cellar/python/3.7.2_2/Frameworks/Python.framework/Versions/3.7/lib/python3.7/threading.py", line 865, in run
    self._target(*self._args, **self._kwargs)
  File "/usr/local/Cellar/python/3.7.2_2/Frameworks/Python.framework/Versions/3.7/lib/python3.7/concurrent/futures/thread.py", line 80, in _worker
    work_item.run()
  File "/usr/local/Cellar/python/3.7.2_2/Frameworks/Python.framework/Versions/3.7/lib/python3.7/concurrent/futures/thread.py", line 57, in run
    result = self.fn(*self.args, **self.kwargs)
  File "/Users/phucluu/Documents/GitHub/django-core-api/polls/start/venv/lib/python3.7/site-packages/asgiref/sync.py", line 248, in _run_event_loop
    loop.run_until_complete(coro)
  File "/usr/local/Cellar/python/3.7.2_2/Frameworks/Python.framework/Versions/3.7/lib/python3.7/asyncio/base_events.py", line 571, in run_until_complete
    self.run_forever()
  File "/usr/local/Cellar/python/3.7.2_2/Frameworks/Python.framework/Versions/3.7/lib/python3.7/asyncio/base_events.py", line 539, in run_forever
    self._run_once()
  File "/usr/local/Cellar/python/3.7.2_2/Frameworks/Python.framework/Versions/3.7/lib/python3.7/asyncio/base_events.py", line 1775, in _run_once
    handle._run()
  File "/usr/local/Cellar/python/3.7.2_2/Frameworks/Python.framework/Versions/3.7/lib/python3.7/asyncio/events.py", line 88, in _run
    self._context.run(self._callback, *self._args)
  File "/Users/phucluu/Documents/GitHub/django-core-api/polls/start/venv/lib/python3.7/site-packages/asgiref/sync.py", line 306, in main_wrap
    result = await self.awaitable(*args, **kwargs)
  File "/Users/phucluu/Documents/GitHub/django-core-api/polls/start/common/decorator.py", line 63, in _func
    log.exception('%s_exception', func.__name__)
  File "/Users/phucluu/Documents/GitHub/django-core-api/polls/start/common/decorator.py", line 56, in _func
    if asyncio.iscoroutinefunction(func):
NameError: name 'asyncio' is not defined

2023-03-02 09:32:35.124|ERROR|7276:123145394458624|logger.py:75|logger._append_exc|test_exception
Traceback (most recent call last):
  File "/usr/local/Cellar/python/3.7.2_2/Frameworks/Python.framework/Versions/3.7/lib/python3.7/threading.py", line 885, in _bootstrap
    self._bootstrap_inner()
  File "/usr/local/Cellar/python/3.7.2_2/Frameworks/Python.framework/Versions/3.7/lib/python3.7/threading.py", line 917, in _bootstrap_inner
    self.run()
  File "/usr/local/Cellar/python/3.7.2_2/Frameworks/Python.framework/Versions/3.7/lib/python3.7/threading.py", line 865, in run
    self._target(*self._args, **self._kwargs)
  File "/usr/local/Cellar/python/3.7.2_2/Frameworks/Python.framework/Versions/3.7/lib/python3.7/concurrent/futures/thread.py", line 80, in _worker
    work_item.run()
  File "/usr/local/Cellar/python/3.7.2_2/Frameworks/Python.framework/Versions/3.7/lib/python3.7/concurrent/futures/thread.py", line 57, in run
    result = self.fn(*self.args, **self.kwargs)
  File "/Users/phucluu/Documents/GitHub/django-core-api/polls/start/venv/lib/python3.7/site-packages/asgiref/sync.py", line 248, in _run_event_loop
    loop.run_until_complete(coro)
  File "/usr/local/Cellar/python/3.7.2_2/Frameworks/Python.framework/Versions/3.7/lib/python3.7/asyncio/base_events.py", line 571, in run_until_complete
    self.run_forever()
  File "/usr/local/Cellar/python/3.7.2_2/Frameworks/Python.framework/Versions/3.7/lib/python3.7/asyncio/base_events.py", line 539, in run_forever
    self._run_once()
  File "/usr/local/Cellar/python/3.7.2_2/Frameworks/Python.framework/Versions/3.7/lib/python3.7/asyncio/base_events.py", line 1775, in _run_once
    handle._run()
  File "/usr/local/Cellar/python/3.7.2_2/Frameworks/Python.framework/Versions/3.7/lib/python3.7/asyncio/events.py", line 88, in _run
    self._context.run(self._callback, *self._args)
  File "/Users/phucluu/Documents/GitHub/django-core-api/polls/start/venv/lib/python3.7/site-packages/asgiref/sync.py", line 306, in main_wrap
    result = await self.awaitable(*args, **kwargs)
  File "/Users/phucluu/Documents/GitHub/django-core-api/polls/start/common/decorator.py", line 64, in _func
    log.exception('%s_exception', func.__name__)
  File "/Users/phucluu/Documents/GitHub/django-core-api/polls/start/common/decorator.py", line 57, in _func
    if asyncio.iscoroutinefunction(func):
NameError: name 'asyncio' is not defined

2023-03-02 09:33:15.132|ERROR|7282:123145521786880|logger.py:75|logger._append_exc|test_exception
Traceback (most recent call last):
  File "/usr/local/Cellar/python/3.7.2_2/Frameworks/Python.framework/Versions/3.7/lib/python3.7/threading.py", line 885, in _bootstrap
    self._bootstrap_inner()
  File "/usr/local/Cellar/python/3.7.2_2/Frameworks/Python.framework/Versions/3.7/lib/python3.7/threading.py", line 917, in _bootstrap_inner
    self.run()
  File "/usr/local/Cellar/python/3.7.2_2/Frameworks/Python.framework/Versions/3.7/lib/python3.7/threading.py", line 865, in run
    self._target(*self._args, **self._kwargs)
  File "/usr/local/Cellar/python/3.7.2_2/Frameworks/Python.framework/Versions/3.7/lib/python3.7/concurrent/futures/thread.py", line 80, in _worker
    work_item.run()
  File "/usr/local/Cellar/python/3.7.2_2/Frameworks/Python.framework/Versions/3.7/lib/python3.7/concurrent/futures/thread.py", line 57, in run
    result = self.fn(*self.args, **self.kwargs)
  File "/Users/phucluu/Documents/GitHub/django-core-api/polls/start/venv/lib/python3.7/site-packages/asgiref/sync.py", line 248, in _run_event_loop
    loop.run_until_complete(coro)
  File "/usr/local/Cellar/python/3.7.2_2/Frameworks/Python.framework/Versions/3.7/lib/python3.7/asyncio/base_events.py", line 571, in run_until_complete
    self.run_forever()
  File "/usr/local/Cellar/python/3.7.2_2/Frameworks/Python.framework/Versions/3.7/lib/python3.7/asyncio/base_events.py", line 539, in run_forever
    self._run_once()
  File "/usr/local/Cellar/python/3.7.2_2/Frameworks/Python.framework/Versions/3.7/lib/python3.7/asyncio/base_events.py", line 1775, in _run_once
    handle._run()
  File "/usr/local/Cellar/python/3.7.2_2/Frameworks/Python.framework/Versions/3.7/lib/python3.7/asyncio/events.py", line 88, in _run
    self._context.run(self._callback, *self._args)
  File "/Users/phucluu/Documents/GitHub/django-core-api/polls/start/venv/lib/python3.7/site-packages/asgiref/sync.py", line 306, in main_wrap
    result = await self.awaitable(*args, **kwargs)
  File "/Users/phucluu/Documents/GitHub/django-core-api/polls/start/common/decorator.py", line 68, in _func
    log.exception('%s_exception', func.__name__)
  File "/Users/phucluu/Documents/GitHub/django-core-api/polls/start/common/decorator.py", line 61, in _func
    if asyncio.iscoroutinefunction(func):
NameError: name 'asyncio' is not defined

2023-03-02 09:34:08.664|ERROR|7306:123145418174464|logger.py:75|logger._append_exc|test_exception
Traceback (most recent call last):
  File "/usr/local/Cellar/python/3.7.2_2/Frameworks/Python.framework/Versions/3.7/lib/python3.7/threading.py", line 885, in _bootstrap
    self._bootstrap_inner()
  File "/usr/local/Cellar/python/3.7.2_2/Frameworks/Python.framework/Versions/3.7/lib/python3.7/threading.py", line 917, in _bootstrap_inner
    self.run()
  File "/usr/local/Cellar/python/3.7.2_2/Frameworks/Python.framework/Versions/3.7/lib/python3.7/threading.py", line 865, in run
    self._target(*self._args, **self._kwargs)
  File "/usr/local/Cellar/python/3.7.2_2/Frameworks/Python.framework/Versions/3.7/lib/python3.7/concurrent/futures/thread.py", line 80, in _worker
    work_item.run()
  File "/usr/local/Cellar/python/3.7.2_2/Frameworks/Python.framework/Versions/3.7/lib/python3.7/concurrent/futures/thread.py", line 57, in run
    result = self.fn(*self.args, **self.kwargs)
  File "/Users/phucluu/Documents/GitHub/django-core-api/polls/start/venv/lib/python3.7/site-packages/asgiref/sync.py", line 248, in _run_event_loop
    loop.run_until_complete(coro)
  File "/usr/local/Cellar/python/3.7.2_2/Frameworks/Python.framework/Versions/3.7/lib/python3.7/asyncio/base_events.py", line 571, in run_until_complete
    self.run_forever()
  File "/usr/local/Cellar/python/3.7.2_2/Frameworks/Python.framework/Versions/3.7/lib/python3.7/asyncio/base_events.py", line 539, in run_forever
    self._run_once()
  File "/usr/local/Cellar/python/3.7.2_2/Frameworks/Python.framework/Versions/3.7/lib/python3.7/asyncio/base_events.py", line 1775, in _run_once
    handle._run()
  File "/usr/local/Cellar/python/3.7.2_2/Frameworks/Python.framework/Versions/3.7/lib/python3.7/asyncio/events.py", line 88, in _run
    self._context.run(self._callback, *self._args)
  File "/Users/phucluu/Documents/GitHub/django-core-api/polls/start/venv/lib/python3.7/site-packages/asgiref/sync.py", line 306, in main_wrap
    result = await self.awaitable(*args, **kwargs)
  File "/Users/phucluu/Documents/GitHub/django-core-api/polls/start/common/decorator.py", line 68, in _func
    log.exception('%s_exception', func.__name__)
  File "/Users/phucluu/Documents/GitHub/django-core-api/polls/start/common/decorator.py", line 61, in _func
    if asyncio.iscoroutinefunction(func):
NameError: name 'asyncio' is not defined

2023-03-02 09:36:17.309|ERROR|7460:123145552416768|users.py:21|users.test|This is log error
2023-03-02 09:36:17.310|ERROR|7460:123145552416768|logger.py:75|logger._append_exc|this is log exception
Traceback (most recent call last):
  File "/usr/local/Cellar/python/3.7.2_2/Frameworks/Python.framework/Versions/3.7/lib/python3.7/threading.py", line 885, in _bootstrap
    self._bootstrap_inner()
  File "/usr/local/Cellar/python/3.7.2_2/Frameworks/Python.framework/Versions/3.7/lib/python3.7/threading.py", line 917, in _bootstrap_inner
    self.run()
  File "/usr/local/Cellar/python/3.7.2_2/Frameworks/Python.framework/Versions/3.7/lib/python3.7/threading.py", line 865, in run
    self._target(*self._args, **self._kwargs)
  File "/usr/local/Cellar/python/3.7.2_2/Frameworks/Python.framework/Versions/3.7/lib/python3.7/concurrent/futures/thread.py", line 80, in _worker
    work_item.run()
  File "/usr/local/Cellar/python/3.7.2_2/Frameworks/Python.framework/Versions/3.7/lib/python3.7/concurrent/futures/thread.py", line 57, in run
    result = self.fn(*self.args, **self.kwargs)
  File "/Users/phucluu/Documents/GitHub/django-core-api/polls/start/venv/lib/python3.7/site-packages/asgiref/sync.py", line 248, in _run_event_loop
    loop.run_until_complete(coro)
  File "/usr/local/Cellar/python/3.7.2_2/Frameworks/Python.framework/Versions/3.7/lib/python3.7/asyncio/base_events.py", line 571, in run_until_complete
    self.run_forever()
  File "/usr/local/Cellar/python/3.7.2_2/Frameworks/Python.framework/Versions/3.7/lib/python3.7/asyncio/base_events.py", line 539, in run_forever
    self._run_once()
  File "/usr/local/Cellar/python/3.7.2_2/Frameworks/Python.framework/Versions/3.7/lib/python3.7/asyncio/base_events.py", line 1775, in _run_once
    handle._run()
  File "/usr/local/Cellar/python/3.7.2_2/Frameworks/Python.framework/Versions/3.7/lib/python3.7/asyncio/events.py", line 88, in _run
    self._context.run(self._callback, *self._args)
  File "/Users/phucluu/Documents/GitHub/django-core-api/polls/start/venv/lib/python3.7/site-packages/asgiref/sync.py", line 306, in main_wrap
    result = await self.awaitable(*args, **kwargs)
  File "/Users/phucluu/Documents/GitHub/django-core-api/polls/start/common/decorator.py", line 65, in _func
    response = func(request, *args, **kwargs)
  File "/Users/phucluu/Documents/GitHub/django-core-api/polls/start/venv/lib/python3.7/site-packages/django/views/decorators/http.py", line 40, in inner
    return func(request, *args, **kwargs)
  File "/Users/phucluu/Documents/GitHub/django-core-api/polls/start/api/users.py", line 23, in test
    log.exception('this is log exception')
None: None

2023-03-02 09:36:17.318|WARNING|7460:123145552416768|users.py:24|users.test|This is log warning
2023-03-02 09:36:17.318|CRITICAL|7460:123145552416768|users.py:26|users.test|This is log fatal
