2023-03-01 04:14:35.813|ERROR|89610:123145452277760|users.py:20|users.test|This is log error
2023-03-01 04:14:35.813|ERROR|89610:123145452277760|logger.py:75|logger._append_exc|this is log exception
Traceback (most recent call last):
  File "/usr/local/Cellar/python/3.7.2_2/Frameworks/Python.framework/Versions/3.7/lib/python3.7/threading.py", line 885, in _bootstrap
    self._bootstrap_inner()
  File "/usr/local/Cellar/python/3.7.2_2/Frameworks/Python.framework/Versions/3.7/lib/python3.7/threading.py", line 917, in _bootstrap_inner
    self.run()
  File "/usr/local/Cellar/python/3.7.2_2/Frameworks/Python.framework/Versions/3.7/lib/python3.7/threading.py", line 865, in run
    self._target(*self._args, **self._kwargs)
  File "/usr/local/Cellar/python/3.7.2_2/Frameworks/Python.framework/Versions/3.7/lib/python3.7/socketserver.py", line 650, in process_request_thread
    self.finish_request(request, client_address)
  File "/usr/local/Cellar/python/3.7.2_2/Frameworks/Python.framework/Versions/3.7/lib/python3.7/socketserver.py", line 360, in finish_request
    self.RequestHandlerClass(request, client_address, self)
  File "/usr/local/Cellar/python/3.7.2_2/Frameworks/Python.framework/Versions/3.7/lib/python3.7/socketserver.py", line 720, in __init__
    self.handle()
  File "/Users/phucluu/PycharmProjects/mysite/venv/lib/python3.7/site-packages/django/core/servers/basehttp.py", line 176, in handle
    self.handle_one_request()
  File "/Users/phucluu/PycharmProjects/mysite/venv/lib/python3.7/site-packages/django/core/servers/basehttp.py", line 201, in handle_one_request
    handler.run(self.server.get_app())
  File "/usr/local/Cellar/python/3.7.2_2/Frameworks/Python.framework/Versions/3.7/lib/python3.7/wsgiref/handlers.py", line 137, in run
    self.result = application(self.environ, self.start_response)
  File "/Users/phucluu/PycharmProjects/mysite/venv/lib/python3.7/site-packages/django/contrib/staticfiles/handlers.py", line 76, in __call__
    return self.application(environ, start_response)
  File "/Users/phucluu/PycharmProjects/mysite/venv/lib/python3.7/site-packages/django/core/handlers/wsgi.py", line 133, in __call__
    response = self.get_response(request)
  File "/Users/phucluu/PycharmProjects/mysite/venv/lib/python3.7/site-packages/django/core/handlers/base.py", line 130, in get_response
    response = self._middleware_chain(request)
  File "/Users/phucluu/PycharmProjects/mysite/venv/lib/python3.7/site-packages/django/core/handlers/exception.py", line 47, in inner
    response = get_response(request)
  File "/Users/phucluu/PycharmProjects/mysite/venv/lib/python3.7/site-packages/django/utils/deprecation.py", line 117, in __call__
    response = response or self.get_response(request)
  File "/Users/phucluu/PycharmProjects/mysite/venv/lib/python3.7/site-packages/django/core/handlers/exception.py", line 47, in inner
    response = get_response(request)
  File "/Users/phucluu/PycharmProjects/mysite/venv/lib/python3.7/site-packages/django/utils/deprecation.py", line 117, in __call__
    response = response or self.get_response(request)
  File "/Users/phucluu/PycharmProjects/mysite/venv/lib/python3.7/site-packages/django/core/handlers/exception.py", line 47, in inner
    response = get_response(request)
  File "/Users/phucluu/PycharmProjects/mysite/venv/lib/python3.7/site-packages/django/utils/deprecation.py", line 117, in __call__
    response = response or self.get_response(request)
  File "/Users/phucluu/PycharmProjects/mysite/venv/lib/python3.7/site-packages/django/core/handlers/exception.py", line 47, in inner
    response = get_response(request)
  File "/Users/phucluu/PycharmProjects/mysite/venv/lib/python3.7/site-packages/django/utils/deprecation.py", line 117, in __call__
    response = response or self.get_response(request)
  File "/Users/phucluu/PycharmProjects/mysite/venv/lib/python3.7/site-packages/django/core/handlers/exception.py", line 47, in inner
    response = get_response(request)
  File "/Users/phucluu/PycharmProjects/mysite/venv/lib/python3.7/site-packages/django/utils/deprecation.py", line 117, in __call__
    response = response or self.get_response(request)
  File "/Users/phucluu/PycharmProjects/mysite/venv/lib/python3.7/site-packages/django/core/handlers/exception.py", line 47, in inner
    response = get_response(request)
  File "/Users/phucluu/PycharmProjects/mysite/venv/lib/python3.7/site-packages/django/utils/deprecation.py", line 117, in __call__
    response = response or self.get_response(request)
  File "/Users/phucluu/PycharmProjects/mysite/venv/lib/python3.7/site-packages/django/core/handlers/exception.py", line 47, in inner
    response = get_response(request)
  File "/Users/phucluu/PycharmProjects/mysite/venv/lib/python3.7/site-packages/django/utils/deprecation.py", line 117, in __call__
    response = response or self.get_response(request)
  File "/Users/phucluu/PycharmProjects/mysite/venv/lib/python3.7/site-packages/django/core/handlers/exception.py", line 47, in inner
    response = get_response(request)
  File "/Users/phucluu/PycharmProjects/mysite/venv/lib/python3.7/site-packages/django/utils/deprecation.py", line 117, in __call__
    response = response or self.get_response(request)
  File "/Users/phucluu/PycharmProjects/mysite/venv/lib/python3.7/site-packages/django/core/handlers/exception.py", line 47, in inner
    response = get_response(request)
  File "/Users/phucluu/PycharmProjects/mysite/venv/lib/python3.7/site-packages/django/core/handlers/base.py", line 181, in _get_response
    response = wrapped_callback(request, *callback_args, **callback_kwargs)
  File "/Users/phucluu/PycharmProjects/mysite/venv/lib/python3.7/site-packages/django/views/decorators/http.py", line 40, in inner
    return func(request, *args, **kwargs)
  File "/Users/phucluu/PycharmProjects/mysite/polls/start/api/users.py", line 22, in test
    log.exception('this is log exception')
None: None

2023-03-01 04:14:35.818|WARNING|89610:123145452277760|users.py:23|users.test|This is log warning
2023-03-01 04:14:35.819|CRITICAL|89610:123145452277760|users.py:25|users.test|This is log fatal
